Workbook

Sheet 1_Raw_Data
A1: ADANI PORTS & RENEWABLE ENERGY — MASTER RAW DATA
A3: TABLE 1 - ANNUAL CARGO THROUGHPUT (FY23–FY25)
A4: Fiscal Year | B4: Cargo (MMT) | C4: YoY Growth | D4: Source
A5: FY2023 | B5: 339 | C5: N/A | D5: Adani Ports Annual Report FY24 p.36
A6: FY2024 | B6: 420 | C6: =(B6-B5)/B5 -> 0.23893805 | D6: Adani Ports Annual Report FY24 — Confirmed 420 MMT
A7: FY2025 | B7: 450 | C7: =(B7-B6)/B6 -> 0.071428571 | D7: APSEZ FY25 Full Year Results
A9: TABLE 2 - PORT-LEVEL CARGO VOLUMES (FY24)
A10: Port | B10: Cargo FY24 (MMT) | C10: % of Total (420 MMT) | D10: Region | E10: Revenue (₹B) | F10: Energy (MW) | G10: Rev/MMT
A11: Mundra | B11: 180 | C11: =B11/420 -> 0.42857143 | D11: West | E11: =350*(B11/221) -> 285.06787 | F11: =7500*(B11/221) -> 6108.5973 | G11: =E11/B11 -> 1.5837104
A12: Krishnapatnam | B12: 59 | C12: =B12/420 -> 0.14047619 | D12: East | E12: =210*(B12/139) -> 89.136691 | F12: =3200*(B12/139) -> 1358.2734 | G12: =E12/B12 -> 1.5107914
A13: Dhamra | B13: 43 | C13: =B13/420 -> 0.10238095 | D13: East | E13: =210*(B13/139) -> 64.964029 | F13: =3200*(B13/139) -> 989.92806 | G13: =E13/B13 -> 1.5107914
A14: Gangavaram | B14: 37 | C14: =B14/420 -> 0.088095238 | D14: East | E14: =210*(B14/139) -> 55.899281 | F14: =3200*(B14/139) -> 851.79856 | G14: =E14/B14 -> 1.5107914
A15: Hazira | B15: 26 | C15: =B15/420 -> 0.061904762 | D15: West | E15: =350*(B15/221) -> 41.176471 | F15: =7500*(B15/221) -> 882.35294 | G15: =E15/B15 -> 1.5837104
A16: Karaikal | B16: 12 | C16: =B16/420 -> 0.028571429 | D16: South | E16: =180*(B16/37) -> 58.378378 | F16: =2600*(B16/37) -> 843.24324 | G16: =E16/B16 -> 4.8648649
A17: Ennore | B17: 13 | C17: =B17/420 -> 0.030952381 | D17: South | E17: =180*(B17/37) -> 63.243243 | F17: =2600*(B17/37) -> 913.51351 | G17: =E17/B17 -> 4.8648649
A18: Kattupalli | B18: 12 | C18: =B18/420 -> 0.028571429 | D18: South | E18: =180*(B18/37) -> 58.378378 | F18: =2600*(B18/37) -> 843.24324 | G18: =E18/B18 -> 4.8648649
A19: Tuna Terminal | B19: 10 | C19: =B19/420 -> 0.023809524 | D19: West | E19: =350*(B19/221) -> 15.837104 | F19: =7500*(B19/221) -> 339.36652 | G19: =E19/B19 -> 1.5837104
A20: Mormugao | B20: 5 | C20: =B20/420 -> 0.011904762 | D20: West | E20: =350*(B20/221) -> 7.918552 | F20: =7500*(B20/221) -> 169.68326 | G20: =E20/B20 -> 1.5837104
A21: Other/International | B21: 23 | C21: =B21/420 -> 0.054761905 | D21: — | E21: N/A | F21: N/A | G21: N/A
A22: TOTAL | B22: =SUM(B11:B21) -> 420 | C22: =SUM(C11:C21) -> 1 | D22: All Regions | E22: =SUM(E11:E21) -> 740 | F22: =SUM(F11:F21) -> 13300
A24: TABLE 3 - MONTHLY CARGO THROUGHPUT
A25: Month | B25: Cargo (MMT) | C25: Cumulative (MMT)
A26: January | B26: 38.6 | C26: =B26 -> 38.6
A27: February | B27: 36.4 | C27: =C26+B27 -> 75
A28: March | B28: 40.1 | C28: =C27+B28 -> 115.1
A29: April | B29: 35.9 | C29: =C28+B29 -> 151
A30: May | B30: 41.8 | C30: =C29+B30 -> 192.8
A31: June | B31: 39.7 | C31: =C30+B31 -> 232.5
A32: July | B32: 37.5 | C32: =C31+B32 -> 270
A33: August | B33: 42.2 | C33: =C32+B33 -> 312.2
A34: September | B34: 39.4 | C34: =C33+B34 -> 351.6
A35: October | B35: 41 | C35: =C34+B35 -> 392.6
A36: November | B36: 40.5 | C36: =C35+B36 -> 433.1
A37: December | B37: 41.9 | C37: =C36+B37 -> 475
A38: ANNUAL TOTAL (Statistical Dataset - 12 months) | B38: =SUM(B26:B37) -> 475 | D38: Target = 475 MMT | Separate from FY25 450 MMT annual report figure
A40: TABLE 4 - REGIONAL OPERATIONAL DATASET
A41: Region | B41: Cargo (MMT) | C41: Revenue (₹ Billion) | D41: Energy (MW) | E41: Revenue / MMT (₹B) | F41: Energy / MMT (MW)
A42: West | B42: 200 | C42: 350 | D42: 7500 | E42: =C42/B42 -> 1.75 | F42: =D42/B42 -> 37.5
A43: East | B43: 110 | C43: 210 | D43: 3200 | E43: =C43/B43 -> 1.9090909 | F43: =D43/B43 -> 29.090909
A44: South | B44: 90 | C44: 180 | D44: 2600 | E44: =C44/B44 -> 2 | F44: =D44/B44 -> 28.888889
...

Sheet 2_Descriptive_Stats
A1: DESCRIPTIVE STATISTICS — CARGO, REVENUE & ENERGY
A3: MONTHLY CARGO THROUGHPUT — DESCRIPTIVE STATS (FY25)
A4: Statistic | B4: Value (MMT)
A5: Mean (Average) | B5: =AVERAGE('1_Raw_Data'!B26:B37) -> 39.583333
A6: Median | B6: =MEDIAN('1_Raw_Data'!B26:B37) -> 39.9
A7: Std Deviation (σ) | B7: =STDEV('1_Raw_Data'!B26:B37) -> 2.1169589
A8: Variance | B8: =VAR('1_Raw_Data'!B26:B37) -> 4.4815152
A9: Minimum | B9: =MIN('1_Raw_Data'!B26:B37) -> 35.9
A10: Maximum | B10: =MAX('1_Raw_Data'!B26:B37) -> 42.2
A11: Range (Max-Min) | B11: =MAX('1_Raw_Data'!B26:B37)-MIN('1_Raw_Data'!B26:B37) -> 6.3
A12: Count (n) | B12: =COUNT('1_Raw_Data'!B26:B37) -> 12
A15: REGIONAL CARGO — DESCRIPTIVE STATS
A16: Statistic | B16: Value (MMT)
A17: Mean Cargo / Region | B17: =AVERAGE('1_Raw_Data'!B42:B45) -> 112.5
A18: Std Deviation (σ) | B18: =STDEV('1_Raw_Data'!B42:B45) -> 63.442888
A19: Minimum | B19: =MIN('1_Raw_Data'!B42:B45) -> 50
A20: Maximum | B20: =MAX('1_Raw_Data'!B42:B45) -> 200
A21: Mean Revenue (₹B) | B21: =AVERAGE('1_Raw_Data'!C42:C45) -> 215
A22: Mean Revenue / MMT | B22: =AVERAGE('1_Raw_Data'!E42:E45) -> 2.0147727
A23: Mean Energy / MMT (MW) | B23: =AVERAGE('1_Raw_Data'!F42:F45) -> 34.869949
A26: KPI SUMMARY METRICS (FOR POWER BI)
A27: KPI | B27: Value | C27: Unit | D27: Notes
A28: Total Cargo Throughput | B28: ='1_Raw_Data'!B38 -> 475 | C28: MMT | D28: Sum of 12 monthly values
A29: Total Renewable Capacity | B29: ='1_Raw_Data'!B53 -> 15538 | C29: MW | D29: Solar+Wind+Hybrid = 15,538 MW
A30: Total Revenue | B30: ='1_Raw_Data'!C46 -> 860 | C30: ₹ Billion | D30: Sum of 4 regions = ₹860B
A31: Peak Monthly Cargo | B31: =MAX('1_Raw_Data'!B26:B37) -> 42.2 | C31: MMT | D31: March 2025
A32: Lowest Monthly Cargo | B32: =MIN('1_Raw_Data'!B26:B37) -> 35.9 | C32: MMT | D32: April 2024
A33: Mundra Share of Total | B33: ='1_Raw_Data'!C11 -> 0.42857143 | C33: % of 420 MMT | D33: ~42.9%
A37: Column1
A39: Mean | B39: 39.583333
A40: Standard Error | B40: 0.61111341
A41: Median | B41: 39.9
A42: Mode | B42: #N/A
A43: Standard Deviation | B43: 2.1169589
A44: Sample Variance | B44: 4.4815152
A45: Kurtosis | B45: -0.80743747
A46: Skewness | B46: -0.54314552
A47: Range | B47: 6.3
A48: Minimum | B48: 35.9
A49: Maximum | B49: 42.2
...

Sheet 3_ANOVA
A1: ANOVA — SINGLE FACTOR: REGIONAL CARGO THROUGHPUT
A3: HYPOTHESIS
A4: H0 (Null): | B4: Regional differences do NOT significantly affect cargo throughput
A5: H1 (Alt): | B5: Regional differences DO significantly affect cargo throughput
A6: Decision Rule: | B6: Reject H0 if p-value < 0.05 (95% confidence level)
A8: INPUT DATA — REGIONAL CARGO (MMT)
A9: Region | B9: Cargo (MMT) | C9: (Group mean) | D9: Deviation from Grand Mean
A10: West | B10: ='1_Raw_Data'!B42 -> 200 | C10: =AVERAGE(B10:B13) -> 112.5 | D10: =B10-$C10 -> 87.5
A11: East | B11: ='1_Raw_Data'!B43 -> 110 | C11: =AVERAGE(B10:B13) -> 112.5 | D11: =B11-$C11 -> -2.5
A12: South | B12: ='1_Raw_Data'!B44 -> 90 | C12: =AVERAGE(B10:B13) -> 112.5 | D12: =B12-$C12 -> -22.5
A13: North | B13: ='1_Raw_Data'!B45 -> 50 | C13: =AVERAGE(B10:B13) -> 112.5 | D13: =B13-$C13 -> -62.5
A14: Grand Mean | B14: =AVERAGE(B10:B13) -> 112.5
A16: ANOVA MANUAL CALCULATIONS (Single Factor, n=1 per group - see limitation note)
A17: Source of Variation | B17: SS | C17: df | D17: MS | E17: F-statistic | F17: p-value (approx) | G17: Critical F (α=0.05)
A18: Between Groups (SSB) | B18: =SUMPRODUCT((B10:B13-B14)^2)*1 -> 12075 | C18: =4-1 -> 3 | D18: =B18/C18 -> 4025 | E18: N/A* | F18: N/A* | G18: N/A*
A19: Within Groups (SSW) | B19: 0 (n=1 per group) | C19: =4*(1-1) -> 0 | D19: Undefined
A20: Total (SST) | B20: =B18+0 -> 12075 | C20: =C18+C19 -> 3
A22: ANOVA-READY DATA — 3-YEAR REPEATED MEASURES (FY23, FY24, FY25 estimated)
A23: Region | B23: FY23 (MMT) | C23: FY24 (MMT) | D23: FY25 (MMT)
A24: West | B24: 151 | C24: 200 | D24: 200
A25: East | B25: 83 | C25: 110 | D25: 110
A26: South | B26: 68 | C26: 90 | D26: 90
A27: North | B27: 38 | C27: 50 | D27: 50
A33: TOOLPAK ANOVA OUTPUT
A34: Source of Variation | B34: SS | C34: df | D34: MS | E34: F | F34: P-value | G34: F crit
A35: Between Groups | B35: 30519.333 | C35: 3 | D35: 10173.111 | E35: 32.484655 | F35: 7.8995795e-05 | G35: 4.0661806
A36: Within Groups | B36: 2505.3333 | C36: 8 | D36: 313.16667
A38: Total | B38: 33024.667 | C38: 11
A40: F-Statistic → | B40: 32.484655 | D40: p-value → | E40: 7.89e-05
A41: Decision (auto): | B41: =IF(E40="","Enter p-value above",IF(E40<0.05,"REJECT H0 - Regional differences are significant","FAIL TO REJECT H0 - No significant difference")) -> REJECT H0 - Regional differences are significant
A43: Anova: Single Factor
A45: SUMMARY
A46: Groups | B46: Count | C46: Sum | D46: Average | E46: Variance
A47: West | B47: 3 | C47: 551 | D47: 183.66667 | E47: 800.33333
A48: East | B48: 3 | C48: 303 | D48: 101 | E48: 243
A49: South | B49: 3 | C49: 248 | D49: 82.666667 | E49: 161.33333
A50: North | B50: 3 | C50: 138 | D50: 46 | E50: 48

Sheet 4_Chi_Square
A1: CHI-SQUARE TEST — CUSTOMER TYPE vs CARGO CATEGORY
A3: HYPOTHESIS
A4: H0: | B4: Customer type does NOT influence cargo category (independent)
A5: H1: | B5: Customer type DOES influence cargo category (dependent)
A7: OBSERVED FREQUENCIES
A8: Customer Type | B8: Bulk Cargo | C8: Container Cargo | D8: Row Total
A9: ='1_Raw_Data'!A57 -> Industrial | B9: ='1_Raw_Data'!B57 -> 240 | C9: ='1_Raw_Data'!C57 -> 110 | D9: =B9+C9 -> 350
A10: ='1_Raw_Data'!A58 -> Retail | B10: ='1_Raw_Data'!B58 -> 70 | C10: ='1_Raw_Data'!C58 -> 80 | D10: =B10+C10 -> 150
A11: Col Total | B11: =SUM(B9:B10) -> 310 | C11: =SUM(C9:C10) -> 190 | D11: =SUM(D9:D10) -> 500
A13: EXPECTED FREQUENCIES - E = (Row Total × Col Total) / Grand Total
A14: Customer Type | B14: Bulk Cargo (E) | C14: Container Cargo (E) | D14: Row Total
A15: Industrial | B15: =$D9*$B$11/$D$11 -> 217 | C15: =$D9*$C$11/$D$11 -> 133 | D15: =B15+C15 -> 350
A16: Retail | B16: =$D10*$B$11/$D$11 -> 93 | C16: =$D10*$C$11/$D$11 -> 57 | D16: =B16+C16 -> 150
A18: CHI-SQUARE CALCULATIONS - (O-E)²/E
A19: Cell | B19: Observed (O) | C19: Expected (E) | D19: (O-E)²/E
A20: Industrial × Bulk | B20: =B9 -> 240 | C20: =B15 -> 217 | D20: =(B20-C20)^2/C20 -> 2.437788
A21: Industrial × Container | B21: =C9 -> 110 | C21: =C15 -> 133 | D21: =(B21-C21)^2/C21 -> 3.9774436
A22: Retail × Bulk | B22: =B10 -> 70 | C22: =B16 -> 93 | D22: =(B22-C22)^2/C22 -> 5.688172
A23: Retail × Container | B23: =C10 -> 80 | C23: =C16 -> 57 | D23: =(B23-C23)^2/C23 -> 9.2807018
A25: CHI-SQUARE TEST RESULTS
A26: χ² Statistic | B26: =SUM(D20:D23) -> 21.384105 | C26: Computed above
A27: Degrees of Freedom (df) | B27: =(2-1)*(2-1) -> 1 | C27: (rows-1)*(cols-1)
A28: Critical Value (α=0.05) | B28: 3.841 | C28: χ²(1, 0.05) = 3.841
A29: p-value | B29: =CHIDIST(B26, B27) -> 3.7587438e-06 | C29: RIGHT-TAIL probability
A30: Decision | B30: =IF(B26 > 3.841, "REJECT H0 - Significant association", "FAIL TO REJECT H0") -> REJECT H0 - Significant association | C30: Compare χ² vs critical

Sheet 5_Normal_Distribution
A1: NORMAL DISTRIBUTION ANALYSIS — EXACT MONTHLY CARGO DATA (Updated per Manager Q4)
A3: DISTRIBUTION PARAMETERS
A4: Parameter | B4: Value | C4: Formula Used
A5: Mean (μ) — Monthly Cargo | B5: =AVERAGE('1_Raw_Data'!B26:B37) -> 39.583333 | C5: AVERAGE(monthly range) — cross-sheet link
A6: Std Dev (σ) | B6: =STDEV('1_Raw_Data'!B26:B37) -> 2.1169589 | C6: STDEV(monthly range) — cross-sheet link
A7: Test Value (x) | B7: 43 | C7: Given in brief: 43 MMT
A9: Z-SCORE & PROBABILITY CALCULATIONS
A10: Calculation | B10: Result | C10: Interpretation
A11: Z-Score = (x - μ) / σ | B11: =(B7-B5)/B6 -> 1.6139504 | C11: Number of std deviations above mean
A12: P(X ≤ 43) — Cumulative | B12: =NORMDIST(B7,B5,B6,TRUE()) -> 0.9467309 | C12: Probability cargo is AT OR BELOW 43 MMT
A13: P(X > 43) — Exceedance | B13: =1-NORMDIST(B7,B5,B6,TRUE()) -> 0.053269096 | C13: Probability cargo EXCEEDS 43 MMT
A14: P(X = 43) — Point probability | B14: =NORMDIST(B7,B5,B6,FALSE()) -> 0.051234762 | C14: Probability density at exactly 43 MMT
A15: P(μ - σ < X < μ + σ) | B15: =NORMDIST(B5+B6,B5,B6,TRUE())-NORMDIST(B5-B6,B5,B6,TRUE()) -> 0.68268949 | C15: ~68% of values in 1 std dev range
A16: 95th Percentile | B16: =NORMINV(0.95,B5,B6) -> 43.065421 | C16: MMT value exceeded only 5% of months
A18: DISTRIBUTION LOOKUP TABLE (Monthly Cargo Scenarios)
A19: Cargo Value (MMT) | B19: P(X ≤ value) | C19: P(X > value)
A20: 35 | B20: =NORMDIST(A20,$B$5,$B$6,TRUE()) -> 0.015191722 | C20: =1-NORMDIST(A20,$B$5,$B$6,TRUE()) -> 0.98480828
A21: 37 | B21: =NORMDIST(A21,$B$5,$B$6,TRUE()) -> 0.11117484 | C21: =1-NORMDIST(A21,$B$5,$B$6,TRUE()) -> 0.88882516
A22: 38 | B22: =NORMDIST(A22,$B$5,$B$6,TRUE()) -> 0.22725173 | C22: =1-NORMDIST(A22,$B$5,$B$6,TRUE()) -> 0.77274827
A23: 39 | B23: =NORMDIST(A23,$B$5,$B$6,TRUE()) -> 0.3914459 | C23: =1-NORMDIST(A23,$B$5,$B$6,TRUE()) -> 0.6085541
A24: 40 | B24: =NORMDIST(A24,$B$5,$B$6,TRUE()) -> 0.57801706 | C24: =1-NORMDIST(A24,$B$5,$B$6,TRUE()) -> 0.42198294
A25: 41 | B25: =NORMDIST(A25,$B$5,$B$6,TRUE()) -> 0.74831571 | C25: =1-NORMDIST(A25,$B$5,$B$6,TRUE()) -> 0.25168429
A26: 42 | B26: =NORMDIST(A26,$B$5,$B$6,TRUE()) -> 0.87318457 | C26: =1-NORMDIST(A26,$B$5,$B$6,TRUE()) -> 0.12681543
A27: 43 | B27: =NORMDIST(A27,$B$5,$B$6,TRUE()) -> 0.9467309 | C27: =1-NORMDIST(A27,$B$5,$B$6,TRUE()) -> 0.053269096
A28: 44 | B28: =NORMDIST(A28,$B$5,$B$6,TRUE()) -> 0.98152545 | C28: =1-NORMDIST(A28,$B$5,$B$6,TRUE()) -> 0.018474547
A29: 45 | B29: =NORMDIST(A29,$B$5,$B$6,TRUE()) -> 0.99474681 | C29: =1-NORMDIST(A29,$B$5,$B$6,TRUE()) -> 0.0052531909

Sheet 6_Forecasting
A1: FORECASTING — ANNUAL & MONTHLY CARGO THROUGHPUT
A3: ANNUAL FORECAST — LINEAR TREND (FY23–FY25 Base)
A4: Fiscal Year | B4: Cargo (MMT) | C4: Year Number (x) | D4: Forecast | E4: Lower Bound | F4: Upper Bound
A5: FY2023 | B5: 339 | C5: 1 | D5: =FORECAST(C5,$B$5:$B$7,$C$5:$C$7) -> 347.5 | E5: =D5*0.9 -> 312.75 | F5: =D5*1.1 -> 382.25
A6: FY2024 | B6: 420 | C6: 2 | D6: =FORECAST(C6,$B$5:$B$7,$C$5:$C$7) -> 403 | E6: =D6*0.9 -> 362.7 | F6: =D6*1.1 -> 443.3
A7: FY2025 | B7: 450 | C7: 3 | D7: =FORECAST(C7,$B$5:$B$7,$C$5:$C$7) -> 458.5 | E7: =D7*0.9 -> 412.65 | F7: =D7*1.1 -> 504.35
A8: FY2026 | B8: — | C8: 4 | D8: =FORECAST(C8,$B$5:$B$7,$C$5:$C$7) -> 514 | E8: =D8*0.9 -> 462.6 | F8: =D8*1.1 -> 565.4
A9: FY2027 | B9: — | C9: 5 | D9: =FORECAST(C9,$B$5:$B$7,$C$5:$C$7) -> 569.5 | E9: =D9*0.9 -> 512.55 | F9: =D9*1.1 -> 626.45
A11: MONTHLY 3-MONTH FORECAST (Apr–Jun FY26) - TREND-BASED
A12: Month | B12: Period (x) | C12: Actual/Forecast (MMT) | D12: Method | E12: Notes
A13: Apr-2024 | B13: 1 | C13: ='1_Raw_Data'!B26 -> 38.6 | D13: Actual
A14: May-2024 | B14: 2 | C14: ='1_Raw_Data'!B27 -> 36.4 | D14: Actual
A15: Jun-2024 | B15: 3 | C15: ='1_Raw_Data'!B28 -> 40.1 | D15: Actual
A16: Jul-2024 | B16: 4 | C16: ='1_Raw_Data'!B29 -> 35.9 | D16: Actual
A17: Aug-2024 | B17: 5 | C17: ='1_Raw_Data'!B30 -> 41.8 | D17: Actual
A18: Sep-2024 | B18: 6 | C18: ='1_Raw_Data'!B31 -> 39.7 | D18: Actual
A19: Oct-2024 | B19: 7 | C19: ='1_Raw_Data'!B32 -> 37.5 | D19: Actual
A20: Nov-2024 | B20: 8 | C20: ='1_Raw_Data'!B33 -> 42.2 | D20: Actual
A21: Dec-2024 | B21: 9 | C21: ='1_Raw_Data'!B34 -> 39.4 | D21: Actual
A22: Jan-2025 | B22: 10 | C22: ='1_Raw_Data'!B35 -> 41 | D22: Actual
A23: Feb-2025 | B23: 11 | C23: ='1_Raw_Data'!B36 -> 40.5 | D23: Actual
A24: Mar-2025 | B24: 12 | C24: ='1_Raw_Data'!B37 -> 41.9 | D24: Actual
A25: Apr-2025 | B25: 13 | C25: =FORECAST(B25,$C$13:$C$24,$B$13:$B$24) -> 41.765152 | D25: FORECAST.LINEAR | E25: FY26 Forecast Month 1
A26: May-2025 | B26: 14 | C26: =FORECAST(B26,$C$13:$C$24,$B$13:$B$24) -> 42.100816 | D26: FORECAST.LINEAR | E26: FY26 Forecast Month 2
A27: Jun-2025 | B27: 15 | C27: =FORECAST(B27,$C$13:$C$24,$B$13:$B$24) -> 42.43648 | D27: FORECAST.LINEAR | E27: FY26 Forecast Month 3

Sheet 7_BI_Dataset
A1: FINAL DATASET FOR POWER BI DASHBOARD
A2: .
A3: Year | B3: Region | C3: Port | D3: Cargo (MMT) | E3: Energy (MW) | F3: Revenue (₹B) | G3: Cargo Type
A4: FY24 | B4: West | C4: Mundra | D4: 180 | E4: 6109 | F4: 285.07 | G4: Mixed
A5: FY24 | B5: East | C5: Krishnapatnam | D5: 59 | E5: 1358 | F5: 89.14 | G5: Dry Bulk
A6: FY24 | B6: East | C6: Dhamra | D6: 43 | E6: 990 | F6: 64.96 | G6: Dry Bulk
A7: FY24 | B7: East | C7: Gangavaram | D7: 37 | E7: 852 | F7: 55.9 | G7: Iron Ore/Coal
A8: FY24 | B8: West | C8: Hazira | D8: 26 | E8: 882 | F8: 41.18 | G8: Containers/LNG
A9: FY24 | B9: South | C9: Karaikal | D9: 12 | E9: 843 | F9: 58.38 | G9: Coal/General
A10: FY24 | B10: South | C10: Ennore | D10: 13 | E10: 914 | F10: 63.24 | G10: Containers
A11: FY24 | B11: South | C11: Kattupalli | D11: 12 | E11: 843 | F11: 58.38 | G11: Containers
A12: FY24 | B12: West | C12: Tuna Terminal | D12: 10 | E12: 339 | F12: 15.84 | G12: Dry Bulk
A13: FY24 | B13: West | C13: Mormugao | D13: 5 | E13: 170 | F13: 7.92 | G13: Coal
A14: FY24 | B14: North | C14: North Ports | D14: 50 | E14: 2200 | F14: 120 | G14: Mixed
A15: FY25 | B15: West | C15: Mundra | D15: 195 | E15: 7500 | F15: 378 | G15: Mixed
... A24: FY25 | B24: West | C24: Mormugao | D24: 6 | E24: 1300 | F24: 38 | G24: Coal
A26: ENERGY MIX TABLE (for Energy Capacity Mix chart in Power BI)
A27: Energy Type | B27: Capacity (MW) | C27: % Share
A28: Solar | B28: 11005 | C28: =B28/SUM(B28:B30) -> 0.70826361
A29: Wind | B29: 1977 | C29: =B29/SUM(B28:B30) -> 0.12723645
A30: Hybrid | B30: 2556 | C30: =B30/SUM(B28:B30) -> 0.16449994
A33: MONTHLY TREND TABLE (for Monthly Cargo Trend chart in Power BI)
A34: Month | B34: Cargo (MMT) | C34: Cumulative (MMT)
A35: ='1_Raw_Data'!A26 -> January | B35: ='1_Raw_Data'!B26 -> 38.6 | C35: ='1_Raw_Data'!C26 -> 38.6
A36: ='1_Raw_Data'!A27 -> February | B36: ='1_Raw_Data'!B27 -> 36.4 | C36: ='1_Raw_Data'!C27 -> 75
A37: ='1_Raw_Data'!A28 -> March | B37: ='1_Raw_Data'!B28 -> 40.1 | C37: ='1_Raw_Data'!C28 -> 115.1
A38: ='1_Raw_Data'!A29 -> April | B38: ='1_Raw_Data'!B29 -> 35.9 | C38: ='1_Raw_Data'!C29 -> 151
A39: ='1_Raw_Data'!A30 -> May | B39: ='1_Raw_Data'!B30 -> 41.8 | C39: ='1_Raw_Data'!C30 -> 192.8
A40: ='1_Raw_Data'!A31 -> June | B40: ='1_Raw_Data'!B31 -> 39.7 | C40: ='1_Raw_Data'!C31 -> 232.5
A41: ='1_Raw_Data'!A32 -> July | B41: ='1_Raw_Data'!B32 -> 37.5 | C41: ='1_Raw_Data'!C32 -> 270
A42: ='1_Raw_Data'!A33 -> August | B42: ='1_Raw_Data'!B33 -> 42.2 | C42: ='1_Raw_Data'!C33 -> 312.2
A43: ='1_Raw_Data'!A34 -> September | B43: ='1_Raw_Data'!B34 -> 39.4 | C43: ='1_Raw_Data'!C34 -> 351.6
A44: ='1_Raw_Data'!A35 -> October | B44: ='1_Raw_Data'!B35 -> 41 | C44: ='1_Raw_Data'!C35 -> 392.6
A45: ='1_Raw_Data'!A36 -> November | B45: ='1_Raw_Data'!B36 -> 40.5 | C45: ='1_Raw_Data'!C36 -> 433.1
A46: ='1_Raw_Data'!A37 -> December | B46: ='1_Raw_Data'!B37 -> 41.9 | C46: ='1_Raw_Data'!C37 -> 475

Sheet 8.  Final Output Summary Sheet
A1: STATISTICAL OUTPUTS
A3: NORMAL DISTRIBUTION: | D3: ANOVA:
A4: Mean (μ) | B4: =AVERAGE('1_Raw_Data'!B26:B37) -> 39.583333 | D4: F-statistic | E4: ='3_ANOVA'!B40 -> 32.484655
A5: Std Dev (σ) | B5: =STDEV('1_Raw_Data'!B26:B37) -> 2.1169589 | D5: P-value | E5: ='3_ANOVA'!E40 -> 7.89e-05
A6: Z-score (43 MMT) | B6: 1.61 | D6: Decision | E6: =IF('3_ANOVA'!E40<0.05,"REJECT H0","FAIL TO REJECT H0") -> REJECT H0
A7: P(X > 43 MMT) | B7: 0.0533
A9: CHI-SQUARE: | D9: FORECASTING:
A10: χ² statistic | B10: 21.38 | D10: FY2026 forecast | E10: ='6_Forecasting'!D8 -> 514
A11: P-value | B11: Approx 0 | D11: FY2027 forecast | E11: ='6_Forecasting'!D9 -> 569.5
A12: Decision | B12: =IF('4_Chi_Square'!B26>3.841,"REJECT H0 Significant association","FAIL TO REJECT H0") -> REJECT H0 Significant association | D12: Jan forecast | E12: ='6_Forecasting'!C25 -> 41.765152
D13: Feb forecast | E13: ='6_Forecasting'!C26 -> 42.100816
A14: DESCRIPTIVE STATS: | D14: Mar forecast | E14: ='6_Forecasting'!C27 -> 42.43648
A15: Monthly Mean | B15: 39.58
A16: Monthly Std Dev | B16: 2.12
A17: Min month | B17: April ( 35.9 )
A18: Max month | B18: August ( 42.2 )
